Workbook

Sheet РядыСтоек1
B1: Плоскость | C1: тип | D1: стойка | E1: поЦентрам | F1: Установка | G1: ДопСтойка
B2: (5-1)-(5-6) | C2: 1 | D2: 1 | E2: 0 | F2: =E2 -> 0
B3: (5-1)-(5-6) | C3: 1 | D3: 2 | E3: 970 | F3: =F2+E3 -> 970
B4: (5-1)-(5-6) | C4: 1 | D4: 3 | E4: 2160 | F4: =F3+E4 -> 3130 | G4: 1
B5: (5-1)-(5-6) | C5: 1 | D5: 4 | E5: 280 | F5: =F4+E5 -> 3410
B6: (5-1)-(5-6) | C6: 1 | D6: 5 | E6: 300 | F6: =F5+E6 -> 3710
B7: (5-1)-(5-6) | C7: 1 | D7: 6 | E7: 960 | F7: =F6+E7 -> 4670
B8: (5-1)-(5-6) | C8: 1 | D8: 7 | E8: 2160 | F8: =F7+E8 -> 6830 | G8: 1
B9: (5-1)-(5-6) | C9: 1 | D9: 8 | E9: 280 | F9: =F8+E9 -> 7110
B10: (5-1)-(5-6) | C10: 1 | D10: 9 | E10: 300 | F10: =F9+E10 -> 7410
B11: (5-1)-(5-6) | C11: 1 | D11: 10 | E11: 930 | F11: =F10+E11 -> 8340 | H11: 5-2
B12: (5-1)-(5-6) | C12: 1 | D12: 11 | E12: 1370 | F12: =F11+E12 -> 9710 | G12: 1
B13: (5-1)-(5-6) | C13: 1 | D13: 12 | E13: 280 | F13: =F12+E13 -> 9990
B14: (5-1)-(5-6) | C14: 1 | D14: 13 | E14: 930 | F14: =F13+E14 -> 10920
B15: (5-1)-(5-6) | C15: 1 | D15: 14 | E15: 300 | F15: =F14+E15 -> 11220
B16: (5-1)-(5-6) | C16: 1 | D16: 15 | E16: 3090 | F16: =F15+E16 -> 14310 | G16: 1 | H16: 5-3 | I16: 5-4
B17: (5-1)-(5-6) | C17: 1 | D17: 16 | E17: 280 | F17: =F16+E17 -> 14590
B18: (5-1)-(5-6) | C18: 1 | D18: 17 | E18: 300 | F18: =F17+E18 -> 14890
B19: (5-1)-(5-6) | C19: 1 | D19: 18 | E19: 930 | F19: =F18+E19 -> 15820
B20: (5-1)-(5-6) | C20: 1 | D20: 19 | E20: 1370 | F20: =F19+E20 -> 17190 | G20: 1
B21: (5-1)-(5-6) | C21: 1 | D21: 20 | E21: 280 | F21: =F20+E21 -> 17470 | H21: 5-5
B22: (5-1)-(5-6) | C22: 1 | D22: 21 | E22: 930 | F22: =F21+E22 -> 18400
B23: (5-1)-(5-6) | C23: 1 | D23: 22 | E23: 300 | F23: =F22+E23 -> 18700
B24: (5-1)-(5-6) | C24: 1 | D24: 23 | E24: 2160 | F24: =F23+E24 -> 20860 | G24: 1
B25: (5-1)-(5-6) | C25: 1 | D25: 24 | E25: 280 | F25: =F24+E25 -> 21140
B26: (5-1)-(5-6) | C26: 1 | D26: 25 | E26: 960 | F26: =F25+E26 -> 22100
B27: (5-1)-(5-6) | C27: 1 | D27: 26 | E27: 300 | F27: =F26+E27 -> 22400
B28: (5-1)-(5-6) | C28: 1 | D28: 27 | E28: 2160 | F28: =F27+E28 -> 24560 | G28: 1
B29: (5-1)-(5-6) | C29: 1 | D29: 28 | E29: 280 | F29: =F28+E29 -> 24840
B30: (5-1)-(5-6) | C30: 1 | D30: 29 | E30: 970 | F30: =F29+E30 -> 25810 | H30: 5-6 | I30: =SUM(E2:E31) -> 25810 | J30: чертёж | K30: 25810
B31: (5-1)-(5-6) | C31: 2 | D31: 1 | E31: 0 | F31: =E31 -> 0
B32: (5-1)-(5-6) | C32: 2 | D32: 2 | E32: 970 | F32: =F31+E32 -> 970
B33: (5-1)-(5-6) | C33: 2 | D33: 3 | E33: 280 | F33: =F32+E33 -> 1250 | G33: 1
B34: (5-1)-(5-6) | C34: 2 | D34: 4 | E34: 2160 | F34: =F33+E34 -> 3410
B35: (5-1)-(5-6) | C35: 2 | D35: 5 | E35: 300 | F35: =F34+E35 -> 3710
B36: (5-1)-(5-6) | C36: 2 | D36: 6 | E36: 960 | F36: =F35+E36 -> 4670
B37: (5-1)-(5-6) | C37: 2 | D37: 7 | E37: 280 | F37: =F36+E37 -> 4950 | G37: 1
B38: (5-1)-(5-6) | C38: 2 | D38: 8 | E38: 2160 | F38: =F37+E38 -> 7110
B39: (5-1)-(5-6) | C39: 2 | D39: 9 | E39: 300 | F39: =F38+E39 -> 7410
B40: (5-1)-(5-6) | C40: 2 | D40: 10 | E40: 930 | F40: =F39+E40 -> 8340 | H40: 5-2
...

Sheet РядыЗаполнений1
A1: Стойка | B1: Зап1 | C1: Зап1_20 | D1: Зап2 | E1: Зап2_57 | F1: Межэтажка | G1: Базовый | H1: ЗапНизВерх | I1: Термомост | J1: ВС | K1: ххх
A2: 0 | B2: Лист 1 мм | C2: Лист 1 мм | D2: Лист 1 мм | E2: Лист 1 мм | F2: Лист 1 мм | G2: Лист 1 мм | H2: Лист 2 мм | I2: =IF(F2="Продлить","Нет","") | K2: ххх
A3: 1 | B3: Тип 10 | C3: Тип 10 | D3: Тип 10 | E3: Тип 8 | F3: Тип 8 | G3: Тип 8 | H3: Лист 2 мм | I3: =IF(F3="Продлить","Нет","") | K3: ххх
A4: 2 | B4: 3а | C4: 3а | D4: НВС | E4: НВС | F4: Продлить | G4: Тип 8 | H4: Лист 2 мм | I4: =IF(F4="Продлить","Нет","") -> Нет | K4: ххх
A5: 3 | B5: НВС | C5: НВС | D5: 3а | E5: 3а | F5: Продлить | G5: Тип 8 | H5: Лист 2 мм | I5: =IF(F5="Продлить","Нет","") -> Нет | K5: ххх
A6: 4 | B6: СН | C6: СН | D6: СН | E6: СН | F6: СН | G6: СН | H6: СН | I6: =IF(F6="Продлить","Нет","") | K6: ххх
A7: 5 | B7: Тип 10 | C7: Тип 10 | D7: Тип 10 | E7: Тип 8 | F7: Тип 8 | G7: Тип 8 | H7: Лист 2 мм | I7: =IF(F7="Продлить","Нет","") | K7: ххх
A8: 6 | B8: 3а | C8: 3а | D8: НВС | E8: НВС | F8: Продлить | G8: Тип 8 | H8: Лист 2 мм | I8: =IF(F8="Продлить","Нет","") -> Нет | K8: ххх
A9: 7 | B9: НВС | C9: НВС | D9: 3а | E9: 3а | F9: Продлить | G9: Тип 8 | H9: Лист 2 мм | I9: =IF(F9="Продлить","Нет","") -> Нет | K9: ххх
A10: 8 | B10: СН | C10: СН | D10: СН | E10: СН | F10: СН | G10: СН | H10: СН | I10: =IF(F10="Продлить","Нет","") | K10: ххх
A11: 9 | B11: Тип 10 | C11: Тип 10 | D11: Тип 10 | E11: Тип 8 | F11: Тип 8 | G11: Тип 8 | H11: Лист 2 мм | I11: =IF(F11="Продлить","Нет","") | K11: ххх
A12: 10 | B12: 5а | C12: 5а | D12: НВС | E12: НВС | F12: Продлить | G12: Тип 8 | H12: Лист 2 мм | I12: =IF(F12="Продлить","Нет","") -> Нет | K12: ххх
A13: 11 | B13: НВС | C13: НВС | D13: 5а | E13: 5а | F13: Продлить | G13: Тип 8 | H13: Лист 2 мм | I13: =IF(F13="Продлить","Нет","") -> Нет | K13: ххх
... A30: 28 | B30: Тип 10 | C30: Тип 10 | D30: Тип 10 | E30: Тип 8 | F30: Продлить | G30: Тип 8 | H30: Лист 2 мм | I30: =IF(F30="Продлить","Нет","") -> Нет | K30: ххх
A31: 29 | H31: Лист 2 мм | I31: =IF(F31="Продлить","Нет","") | K31: ххх

Sheet РядыКреплений1
A1: пл1_Зап1 | B1: пл1_Зап2 | C1: Стойка | D1: Креп1 | E1: Креп1_20 | F1: Подпорка1 | G1: Подпорка1_20 | H1: Креп2 | I1: Креп2_57 | J1: Подпорка2 | K1: Подпорка2_57 | L1: КрепМ | M1: КрепМ_Ус | N1: ВС | O1: ххх
A2: Лист 1 мм | B2: Лист 1 мм | C2: 0
A3: Тип 10 | B3: Тип 10 | C3: 1 | D3: с2 | E3: с2 | H3: с2 | I3: с2 | L3: с2 | M3: с3
A4: 3а | B4: НВС | C4: 2 | D4: с3 | E4: с3 | F4: Подпорка | H4: с2 | I4: с2 | L4: с2 | M4: с2
A5: НВС | B5: 3а | C5: 3 | D5: с2 | E5: с2 | H5: с3 | I5: с3 | J5: Подпорка | K5: Подпорка | L5: с2 | M5: с3
A6: СН | B6: СН | C6: 4 | D6: с1 | E6: с1 | H6: с1 | I6: с1 | L6: с1 | M6: с1
A7: Тип 10 | B7: Тип 10 | C7: 5 | D7: с2 | E7: с2 | H7: с2 | I7: с2 | L7: с2 | M7: с3
A8: 3а | B8: НВС | C8: 6 | D8: с3 | E8: с3 | F8: Подпорка | H8: с2 | I8: с2 | L8: с2 | M8: с2
A9: НВС | B9: 3а | C9: 7 | D9: с2 | E9: с2 | H9: с3 | I9: с3 | J9: Подпорка | K9: Подпорка | L9: с2 | M9: с3
A10: СН | B10: СН | C10: 8 | D10: с1 | E10: с1 | H10: с1 | I10: с1 | L10: с1 | M10: с1
A11: Тип 10 | B11: Тип 10 | C11: 9 | D11: с2 | E11: с2 | H11: с2 | I11: с2 | L11: с2 | M11: с3
A12: 5а | B12: НВС | C12: 10 | D12: с3 | E12: с2 | H12: с2 | I12: с2 | L12: с2 | M12: с2
A13: НВС | B13: 5а | C13: 11 | D13: с2 | E13: с2 | H13: с3 | I13: с3 | L13: с2 | M13: с2
A14: Тип 10 | B14: Тип 10 | C14: 12 | D14: с2 | E14: с2 | H14: с2 | I14: с2 | L14: с2 | M14: с3
A15: СН | B15: СН | C15: 13 | D15: с1 | E15: с1 | H15: с1 | I15: с1 | L15: с1 | M15: с1
A16: 1а | B16: НВС | C16: 14 | D16: с3 | E16: с3 | F16: Подпорка | G16: Подпорка | H16: с2 | I16: с80 | L16: с2 | M16: с3
A17: НВС | B17: 1а | C17: 15 | D17: с2 | E17: с2 | H17: с3 | I17: с6 | J17: Подпорка | L17: с2 | M17: с3
A18: СН | B18: СН | C18: 16 | D18: с1 | E18: с1 | H18: с1 | I18: с1 | L18: с1 | M18: с1
A19: Тип 10 | B19: Тип 10 | C19: 17 | D19: с2 | E19: с2 | H19: с2 | I19: с2 | L19: с2 | M19: с3
A20: 5а | B20: НВС | C20: 18 | D20: с3 | E20: с2 | H20: с2 | I20: с2 | L20: с2 | M20: с2
A21: НВС | B21: 5а | C21: 19 | D21: с2 | E21: с2 | H21: с3 | I21: с3 | L21: с2 | M21: с2
A22: Тип 10 | B22: Тип 10 | C22: 20 | D22: с2 | E22: с2 | H22: с2 | I22: с2 | L22: с2 | M22: с3
A23: СН | B23: СН | C23: 21 | D23: с1 | E23: с1 | H23: с1 | I23: с1 | L23: с1 | M23: с1
A24: 3а | B24: НВС | C24: 22 | D24: с3 | E24: с3 | F24: Подпорка | H24: с2 | I24: с2 | L24: с2 | M24: с3
A25: НВС | B25: 3а | C25: 23 | D25: с2 | E25: с2 | H25: с3 | I25: с3 | J25: Подпорка | K25: Подпорка | L25: с2 | M25: с2
A26: Тип 10 | B26: Тип 10 | C26: 24 | D26: с2 | E26: с2 | H26: с2 | I26: с2 | L26: с2 | M26: с3
A27: СН | B27: СН | C27: 25 | D27: с1 | E27: с1 | H27: с1 | I27: с1 | L27: с1 | M27: с1
A28: 3а | B28: НВС | C28: 26 | D28: с3 | E28: с3 | F28: Подпорка | H28: с2 | I28: с2 | L28: с2 | M28: с3
A29: НВС | B29: 3а | C29: 27 | D29: с2 | E29: с2 | H29: с3 | I29: с3 | J29: Подпорка | K29: Подпорка | L29: с2 | M29: с2
A30: Тип 10 | B30: Тип 10 | C30: 28 | D30: с2 | E30: с2 | H30: с2 | I30: с2 | L30: с2 | M30: с3
C31: 29

Sheet РядыОпор1
A1: =РядыЗаполнений1!B1 -> Зап1 | B1: =РядыЗаполнений1!D1 -> Зап2 | C1: Стойка | D1: ОпораМ | E1: ОпораМ_Ус | F1: Опора1 | G1: Опора1_20 | H1: Опора1_40 | I1: Опора2 | J1: Опора2_57 | K1: ВС
A2: =РядыЗаполнений1!B2 -> Лист 1 мм | B2: =РядыЗаполнений1!D2 -> Лист 1 мм | C2: 0
A3: =РядыЗаполнений1!B3 -> Тип 10 | B3: =РядыЗаполнений1!D3 -> Тип 10 | C3: 1 | D3: о1лев | E3: о3лев | F3: о1 | G3: о1 | H3: о1 | I3: о1 | J3: о1
A4: =РядыЗаполнений1!B4 -> 3а | B4: =РядыЗаполнений1!D4 -> НВС | C4: 2 | F4: о3 | G4: о3 | H4: о3 | I4: о1ц
A5: =РядыЗаполнений1!B5 -> НВС | B5: =РядыЗаполнений1!D5 -> 3а | C5: 3 | D5: о1прав | E5: о3прав | F5: о1ц | G5: о1ц | H5: о1ц | I5: о3 | J5: о4
A6: =РядыЗаполнений1!B6 -> СН | B6: =РядыЗаполнений1!D6 -> СН | C6: 4 | D6: о1ц | E6: о1ц | F6: о1ц | G6: о1ц | H6: о1ц | I6: о1ц
A7: =РядыЗаполнений1!B7 -> Тип 10 | B7: =РядыЗаполнений1!D7 -> Тип 10 | C7: 5 | D7: о1лев | E7: о3лев | F7: о1 | G7: о1 | H7: о1 | I7: о1 | J7: о1
A8: =РядыЗаполнений1!B8 -> 3а | B8: =РядыЗаполнений1!D8 -> НВС | C8: 6 | F8: о3 | G8: о3 | H8: о3 | I8: о1ц
A9: =РядыЗаполнений1!B9 -> НВС | B9: =РядыЗаполнений1!D9 -> 3а | C9: 7 | D9: о1прав | E9: о3прав | F9: о1ц | G9: о1ц | H9: о1ц | I9: о3 | J9: о4
A10: =РядыЗаполнений1!B10 -> СН | B10: =РядыЗаполнений1!D10 -> СН | C10: 8 | D10: о1ц | E10: о1ц | F10: о1ц | G10: о1ц | H10: о1ц | I10: о1ц
A11: =РядыЗаполнений1!B11 -> Тип 10 | B11: =РядыЗаполнений1!D11 -> Тип 10 | C11: 9 | D11: о1лев | E11: о3лев | F11: о1 | G11: о1 | H11: о1 | I11: о1 | J11: о1
A12: =РядыЗаполнений1!B12 -> 5а | B12: =РядыЗаполнений1!D12 -> НВС | C12: 10 | F12: о3 | G12: о2 | H12: о2 | I12: о1ц | J12: о1ц
A13: =РядыЗаполнений1!B13 -> НВС | B13: =РядыЗаполнений1!D13 -> 5а | C13: 11 | F13: о1ц | G13: о1ц | H13: о1ц | I13: о3 | J13: о3
A14: =РядыЗаполнений1!B14 -> Тип 10 | B14: =РядыЗаполнений1!D14 -> Тип 10 | C14: 12 | D14: о1прав | E14: о3прав | F14: о1 | G14: о1 | H14: о1 | I14: о1 | J14: о1
A15: =РядыЗаполнений1!B15 -> СН | B15: =РядыЗаполнений1!D15 -> СН | C15: 13 | D15: о1ц | E15: о1ц | H15: о1ц | I15: о1ц | J15: о1ц
A16: =РядыЗаполнений1!B16 -> 1а | B16: =РядыЗаполнений1!D16 -> НВС | C16: 14 | D16: о1лев | E16: о3лев | F16: о4 | G16: о4 | H16: о3 | J16: о1ц
A17: =РядыЗаполнений1!B17 -> НВС | B17: =РядыЗаполнений1!D17 -> 1а | C17: 15 | D17: о1прав | E17: о3прав | H17: о1ц | I17: о4 | J17: о5
A18: =РядыЗаполнений1!B18 -> СН | B18: =РядыЗаполнений1!D18 -> СН | C18: 16 | D18: о1ц | E18: о1ц | F18: о1ц | G18: о1ц | H18: о1ц | J18: о1ц
A19: =РядыЗаполнений1!B19 -> Тип 10 | B19: =РядыЗаполнений1!D19 -> Тип 10 | C19: 17 | D19: о1лев | E19: о3лев | F19: о1 | G19: о1 | H19: о1 | I19: о1 | J19: о1
A20: =РядыЗаполнений1!B20 -> 5а | B20: =РядыЗаполнений1!D20 -> НВС | C20: 18 | F20: о3 | G20: о2 | H20: о2 | I20: о1ц | J20: о1ц
A21: =РядыЗаполнений1!B21 -> НВС | B21: =РядыЗаполнений1!D21 -> 5а | C21: 19 | F21: о1ц | G21: о1ц | H21: о1ц | I21: о3 | J21: о3
A22: =РядыЗаполнений1!B22 -> Тип 10 | B22: =РядыЗаполнений1!D22 -> Тип 10 | C22: 20 | D22: о1прав | E22: о3прав | F22: о1 | G22: о1 | H22: о1 | I22: о1 | J22: о1
A23: =РядыЗаполнений1!B23 -> СН | B23: =РядыЗаполнений1!D23 -> СН | C23: 21 | D23: о1ц | E23: о1ц | F23: о1ц | G23: о1ц | H23: о1ц | I23: о1ц | J23: о1ц
A24: =РядыЗаполнений1!B24 -> 3а | B24: =РядыЗаполнений1!D24 -> НВС | C24: 22 | D24: о1лев | E24: о3лев | F24: о3 | G24: о3 | H24: о3 | I24: о1ц
A25: =РядыЗаполнений1!B25 -> НВС | B25: =РядыЗаполнений1!D25 -> 3а | C25: 23 | F25: о1ц | G25: о1ц | H25: о1ц | I25: о3 | J25: о4
A26: =РядыЗаполнений1!B26 -> Тип 10 | B26: =РядыЗаполнений1!D26 -> Тип 10 | C26: 24 | D26: о1прав | E26: о3прав | F26: о1 | G26: о1 | H26: о1 | I26: о1 | J26: о1прав
A27: =РядыЗаполнений1!B27 -> СН | B27: =РядыЗаполнений1!D27 -> СН | C27: 25 | D27: о1ц | E27: о1ц | F27: о1ц | G27: о1ц | H27: о1ц | I27: о1ц | J27: о1ц
A28: =РядыЗаполнений1!B28 -> 3а | B28: =РядыЗаполнений1!D28 -> НВС | C28: 26 | D28: о1лев | E28: о3лев | F28: о3 | G28: о3 | H28: о3 | I28: о1ц
A29: =РядыЗаполнений1!B29 -> НВС | B29: =РядыЗаполнений1!D29 -> 3а | C29: 27 | F29: о1ц | G29: о1ц | H29: о1ц | I29: о3 | J29: о4
A30: =РядыЗаполнений1!B30 -> Тип 10 | B30: =РядыЗаполнений1!D30 -> Тип 10 | C30: 28 | D30: о1прав | E30: о3прав | F30: о1 | G30: о1 | H30: о1 | I30: о1 | J30: о1прав
C31: 29

Sheet РядыРигелей1
A1: Этаж | B1: НизСтойки | C1: ВысотаСтойки | D1: Зазор | E1: РядИзделия | F1: РядФасада | G1: ПоЦентрам | H1: Установка | I1: ТипРядовСтоек | J1: ТипРядовЗаполнений | K1: ТипКреплений | L1: Подпорки | M1: Опоры | O1: Уровень ЧП | P1: Низ Окна | Q1: РучкаотНизаОкна
A2: 0 | B2: 0 | C2: 0 | D2: 0 | E2: 0 | F2: 0 | G2: 0 | H2: 0 | I2: 1 | J2: ЗапНизВерх
A3: 2 | B3: 7670 | C3: 3770 | D3: 10 | E3: 1 | F3: 1 | G3: 25 | H3: =G3+B3 -> 7695 | I3: 1 | J3: Межэтажка | K3: КрепМ | M3: ОпораМ | O3: 8360
A4: 2 | E4: 2 | F4: 2 | G4: 690 | H4: =H3+G4 -> 8385 | J4: Зап1 | K4: Креп1 | L4: Подпорка1 | M4: Опора1 | S4: Этаж | T4: Ригель | U4: чп | V4: ОтЦентра | W4: низОкна
A5: 2 | E5: 3 | F5: 3 | G5: 950 | H5: =H4+G5 -> 9335 | J5: ВС | K5: ВС | M5: ВС | P5: =H5-O3+13 -> 988 | Q5: =1600-P5 -> 612 | S5: 2 | T5: =8385+950 -> 9335 | U5: 8360 | V5: 13 | W5: =T5-U5+V5 -> 988
A6: 2 | E6: 4 | F6: 4 | G6: 1720 | H6: =H5+G6 -> 11055 | J6: Межэтажка | K6: КрепМ | M6: ОпораМ
A7: 3 | B7: 11450 | C7: 3350 | D7: 10 | E7: 1 | F7: 5 | G7: 690 | H7: =H6+G7 -> 11745 | I7: 2 | J7: Зап2 | K7: Креп2 | L7: Подпорка2 | M7: Опора2 | O7: 11720 | S7: 19 | T7: 66455 | U7: 65480 | V7: 13 | W7: =T7-U7+V7 -> 988
A8: 3 | E8: 2 | F8: 6 | G8: 950 | H8: =H7+G8 -> 12695 | J8: ВС | K8: ВС | M8: ВС | P8: =H8-O7+13 -> 988 | Q8: =1600-P8 -> 612 | S8: 20 | T8: 69975 | U8: 69000 | V8: 13 | W8: =T8-U8+V8 -> 988
A9: 3 | E9: 3 | F9: 7 | G9: 1720 | H9: =H8+G9 -> 14415 | J9: Межэтажка | K9: КрепМ | M9: ОпораМ | S9: 21 | T9: 73335 | U9: 72360 | V9: 13 | W9: =T9-U9+V9 -> 988
A10: =A7+1 -> 4 | B10: =B7+C7+D7 -> 14810 | C10: =$C$7 -> 3350 | D10: 10 | E10: =E7 -> 1 | F10: 8 | G10: =$G$7 -> 690 | H10: =H9+G10 -> 15105 | I10: 1 | J10: Зап1 | K10: Креп1 | L10: Подпорка1 | M10: Опора1 | O10: =O7+C7+D7 -> 15080
A11: =A8+1 -> 4 | E11: =E8 -> 2 | F11: 9 | G11: =$G$8 -> 950 | H11: =H10+G11 -> 16055 | J11: ВС | K11: ВС | M11: ВС | P11: =H11-O10+13 -> 988 | Q11: =1600-P11 -> 612 | S11: 39 | T11: 133815 | U11: 132840 | V11: 13 | W11: =T11-U11+V11 -> 988
A12: =A9+1 -> 4 | E12: =E9 -> 3 | F12: 10 | G12: =$G$9 -> 1720 | H12: =H11+G12 -> 17775 | J12: Межэтажка | K12: КрепМ | M12: ОпораМ | S12: 40 | T12: 137335 | U12: 136360 | V12: 13 | W12: =T12-U12+V12 -> 988
A13: =A10+1 -> 5 | B13: =B10+C10+D10 -> 18170 | C13: =$C$7 -> 3350 | D13: 10 | E13: =E10 -> 1 | F13: 11 | G13: =$G$7 -> 690 | H13: =H12+G13 -> 18465 | I13: 2 | J13: Зап2 | K13: Креп2 | L13: Подпорка2 | M13: Опора2 | O13: =O10+C10+D10 -> 18440 | S13: 41 | T13: 140695 | U13: 139720 | V13: 13 | W13: =T13-U13+V13 -> 988
A14: =A11+1 -> 5 | E14: =E11 -> 2 | F14: 12 | G14: =$G$8 -> 950 | H14: =H13+G14 -> 19415 | J14: ВС | K14: ВС | M14: ВС | P14: =H14-O13+13 -> 988 | Q14: =1600-P14 -> 612
A15: =A12+1 -> 5 | E15: =E12 -> 3 | F15: 13 | G15: =$G$9 -> 1720 | H15: =H14+G15 -> 21135 | J15: Межэтажка | K15: КрепМ | M15: ОпораМ | S15: 57 | T15: 194455 | U15: 193480 | V15: 13 | W15: =T15-U15+V15 -> 988
A16: =A13+1 -> 6 | B16: =B13+C13+D13 -> 21530 | C16: =$C$7 -> 3350 | D16: 10 | E16: =E13 -> 1 | F16: 14 | G16: =$G$7 -> 690 | H16: =H15+G16 -> 21825 | I16: 1 | J16: Зап1 | K16: Креп1 | L16: Подпорка1 | M16: Опора1 | O16: =O13+C13+D13 -> 21800
A17: =A14+1 -> 6 | E17: =E14 -> 2 | F17: 15 | G17: =$G$8 -> 950 | H17: =H16+G17 -> 22775 | J17: ВС | K17: ВС | M17: ВС | P17: =H17-O16+13 -> 988 | Q17: =1600-P17 -> 612
A18: =A15+1 -> 6 | E18: =E15 -> 3 | F18: 16 | G18: =$G$9 -> 1720 | H18: =H17+G18 -> 24495 | J18: Межэтажка | K18: КрепМ | M18: ОпораМ
A19: =A16+1 -> 7 | B19: =B16+C16+D16 -> 24890 | C19: =$C$7 -> 3350 | D19: 10 | E19: =E16 -> 1 | F19: 17 | G19: =$G$7 -> 690 | H19: =H18+G19 -> 25185 | I19: 2 | J19: Зап2 | K19: Креп2 | L19: Подпорка2 | M19: Опора2 | O19: =O16+C16+D16 -> 25160
A20: =A17+1 -> 7 | E20: =E17 -> 2 | F20: 18 | G20: =$G$8 -> 950 | H20: =H19+G20 -> 26135 | J20: ВС | K20: ВС | M20: ВС | P20: =H20-O19+13 -> 988 | Q20: =1600-P20 -> 612
A21: =A18+1 -> 7 | E21: =E18 -> 3 | F21: 19 | G21: =$G$9 -> 1720 | H21: =H20+G21 -> 27855 | J21: Межэтажка | K21: КрепМ | M21: ОпораМ
A22: =A19+1 -> 8 | B22: =B19+C19+D19 -> 28250 | C22: =$C$7 -> 3350 | D22: 10 | E22: =E19 -> 1 | F22: 20 | G22: =$G$7 -> 690 | H22: =H21+G22 -> 28545 | I22: 1 | J22: Зап1 | K22: Креп1 | L22: Подпорка1 | M22: Опора1 | O22: =O19+C19+D19 -> 28520
A23: =A20+1 -> 8 | E23: =E20 -> 2 | F23: 21 | G23: =$G$8 -> 950 | H23: =H22+G23 -> 29495 | J23: ВС | K23: ВС | M23: ВС | P23: =H23-O22+13 -> 988 | Q23: =1600-P23 -> 612
A24: =A21+1 -> 8 | E24: =E21 -> 3 | F24: 22 | G24: =$G$9 -> 1720 | H24: =H23+G24 -> 31215 | J24: Межэтажка | K24: КрепМ | M24: ОпораМ
A25: =A22+1 -> 9 | B25: =B22+C22+D22 -> 31610 | C25: =$C$7 -> 3350 | D25: 10 | E25: =E22 -> 1 | F25: 23 | G25: =$G$7 -> 690 | H25: =H24+G25 -> 31905 | I25: 2 | J25: Зап2 | K25: Креп2 | L25: Подпорка2 | M25: Опора2 | O25: =O22+C22+D22 -> 31880
A26: =A23+1 -> 9 | E26: =E23 -> 2 | F26: 24 | G26: =$G$8 -> 950 | H26: =H25+G26 -> 32855 | J26: ВС | K26: ВС | M26: ВС | P26: =H26-O25+13 -> 988 | Q26: =1600-P26 -> 612
A27: =A24+1 -> 9 | E27: =E24 -> 3 | F27: 25 | G27: =$G$9 -> 1720 | H27: =H26+G27 -> 34575 | J27: Межэтажка | K27: КрепМ | M27: ОпораМ
A28: =A25+1 -> 10 | B28: =B25+C25+D25 -> 34970 | C28: =$C$7 -> 3350 | D28: 10 | E28: =E25 -> 1 | F28: 26 | G28: =$G$7 -> 690 | H28: =H27+G28 -> 35265 | I28: 1 | J28: Зап1 | K28: Креп1 | L28: Подпорка1 | M28: Опора1 | O28: =O25+C25+D25 -> 35240
A29: =A26+1 -> 10 | E29: =E26 -> 2 | F29: 27 | G29: =$G$8 -> 950 | H29: =H28+G29 -> 36215 | J29: ВС | K29: ВС | M29: ВС | P29: =H29-O28+13 -> 988 | Q29: =1600-P29 -> 612
A30: =A27+1 -> 10 | E30: =E27 -> 3 | F30: 28 | G30: =$G$9 -> 1720 | H30: =H29+G30 -> 37935 | J30: Межэтажка | K30: КрепМ | M30: ОпораМ
A31: =A28+1 -> 11 | B31: =B28+C28+D28 -> 38330 | C31: =$C$7 -> 3350 | D31: 10 | E31: =E28 -> 1 | F31: 29 | G31: =$G$7 -> 690 | H31: =H30+G31 -> 38625 | I31: 2 | J31: Зап2 | K31: Креп2 | L31: Подпорка2 | M31: Опора2 | O31: =O28+C28+D28 -> 38600
A32: =A29+1 -> 11 | E32: =E29 -> 2 | F32: 30 | G32: =$G$8 -> 950 | H32: =H31+G32 -> 39575 | J32: ВС | K32: ВС | M32: ВС | P32: =H32-O31+13 -> 988 | Q32: =1600-P32 -> 612
A33: =A30+1 -> 11 | E33: =E30 -> 3 | F33: 31 | G33: =$G$9 -> 1720 | H33: =H32+G33 -> 41295 | J33: Межэтажка | K33: КрепМ | M33: ОпораМ
A34: =A31+1 -> 12 | B34: =B31+C31+D31 -> 41690 | C34: =$C$7 -> 3350 | D34: 10 | E34: =E31 -> 1 | F34: 32 | G34: =$G$7 -> 690 | H34: =H33+G34 -> 41985 | I34: 1 | J34: Зап1 | K34: Креп1 | L34: Подпорка1 | M34: Опора1 | O34: =O31+C31+D31 -> 41960
A35: =A32+1 -> 12 | E35: =E32 -> 2 | F35: 33 | G35: =$G$8 -> 950 | H35: =H34+G35 -> 42935 | J35: ВС | K35: ВС | M35: ВС | P35: =H35-O34+13 -> 988 | Q35: =1600-P35 -> 612
A36: =A33+1 -> 12 | E36: =E33 -> 3 | F36: 34 | G36: =$G$9 -> 1720 | H36: =H35+G36 -> 44655 | J36: Межэтажка | K36: КрепМ | M36: ОпораМ
A37: =A34+1 -> 13 | B37: =B34+C34+D34 -> 45050 | C37: =$C$7 -> 3350 | D37: 10 | E37: =E34 -> 1 | F37: 35 | G37: =$G$7 -> 690 | H37: =H36+G37 -> 45345 | I37: 2 | J37: Зап2 | K37: Креп2 | L37: Подпорка2 | M37: Опора2 | O37: =O34+C34+D34 -> 45320
A38: =A35+1 -> 13 | E38: =E35 -> 2 | F38: 36 | G38: =$G$8 -> 950 | H38: =H37+G38 -> 46295 | J38: ВС | K38: ВС | M38: ВС | P38: =H38-O37+13 -> 988 | Q38: =1600-P38 -> 612
A39: =A36+1 -> 13 | E39: =E36 -> 3 | F39: 37 | G39: =$G$9 -> 1720 | H39: =H38+G39 -> 48015 | J39: Межэтажка | K39: КрепМ | M39: ОпораМ
A40: =A37+1 -> 14 | B40: =B37+C37+D37 -> 48410 | C40: =$C$7 -> 3350 | D40: 10 | E40: =E37 -> 1 | F40: 38 | G40: =$G$7 -> 690 | H40: =H39+G40 -> 48705 | I40: 1 | J40: Зап1 | K40: Креп1 | L40: Подпорка1 | M40: Опора1 | O40: =O37+C37+D37 -> 48680
...

Sheet ГраницыИзделий1
A1: Стойка | B1: ЛеваяСтойка | C1: ПраваяСтойка | D1: НомерИзделия
A2: 1 | B2: 1 | C2: 4 | D2: 1
A3: 2 | B3: 1 | C3: 4 | D3: 1
A4: 3 | B4: 1 | C4: 4 | D4: 1
A5: 4 | B5: 1 | C5: 4 | D5: 1
A6: 5 | B6: 5 | C6: 8 | D6: 2
A7: 6 | B7: 5 | C7: 8 | D7: 2
A8: 7 | B8: 5 | C8: 8 | D8: 2
A9: 8 | B9: 5 | C9: 8 | D9: 2
A10: 9 | B10: 9 | C10: 13 | D10: 3
A11: 10 | B11: 9 | C11: 13 | D11: 3
A12: 11 | B12: 9 | C12: 13 | D12: 3
A13: 12 | B13: 9 | C13: 13 | D13: 3
... A30: 29 | B30: 26 | C30: 29 | D30: 7

Sheet Изделия1
A1: Этаж | B1: с1 | C1: с5 | D1: с9 | E1: с14 | F1: с17 | G1: с22 | H1: с26 | J1: Изделия на этаже
A2: 57 | B2: ВН-53-К5(а) | C2: ВН-54-К5(а) | D2: ВН-55-К5(а) | E2: ВН-56-К5(а) | F2: ВН-55-К5(а) | G2: ВН-57-К5(а) | H2: ВН-58-К5(а) | J2: =_xlfn.CONCAT(B2,", ",C2,", ",D2,", ",E2,", ", F2,", ",G2,", ",H2) -> ВН-53-К5(а), ВН-54-К5(а), ВН-55-К5(а), ВН-56-К5(а), ВН-55-К5(а), ВН-57-К5(а), ВН-58-К5(а)
A3: 56 | B3: ВН-29-К5(а) | C3: ВН-30-К5(а) | D3: ВН-31-К5(а) | E3: ВН-32-К5(а) | F3: ВН-31-К5(а) | G3: ВН-33-К5(а) | H3: ВН-34-К5(а)
A4: 55 | B4: ВН-35-К5(а) | C4: ВН-36-К5(а) | D4: ВН-37-К5(а) | E4: ВН-38-К5(а) | F4: ВН-37-К5(а) | G4: ВН-39-К5(а) | H4: ВН-40-К5(а)
A5: 54 | B5: ВН-29-К5(а) | C5: ВН-30-К5(а) | D5: ВН-31-К5(а) | E5: ВН-32-К5(а) | F5: ВН-31-К5(а) | G5: ВН-33-К5(а) | H5: ВН-34-К5(а)
A6: 53 | B6: ВН-35-К5(а) | C6: ВН-36-К5(а) | D6: ВН-37-К5(а) | E6: ВН-38-К5(а) | F6: ВН-37-К5(а) | G6: ВН-39-К5(а) | H6: ВН-40-К5(а)
A7: 52 | B7: ВН-29-К5(а) | C7: ВН-30-К5(а) | D7: ВН-31-К5(а) | E7: ВН-32-К5(а) | F7: ВН-31-К5(а) | G7: ВН-33-К5(а) | H7: ВН-34-К5(а)
A8: 51 | B8: ВН-35-К5(а) | C8: ВН-36-К5(а) | D8: ВН-37-К5(а) | E8: ВН-38-К5(а) | F8: ВН-37-К5(а) | G8: ВН-39-К5(а) | H8: ВН-40-К5(а)
A9: 50 | B9: ВН-29-К5(а) | C9: ВН-30-К5(а) | D9: ВН-31-К5(а) | E9: ВН-32-К5(а) | F9: ВН-31-К5(а) | G9: ВН-33-К5(а) | H9: ВН-34-К5(а)
A10: 49 | B10: ВН-35-К5(а) | C10: ВН-36-К5(а) | D10: ВН-37-К5(а) | E10: ВН-38-К5(а) | F10: ВН-37-К5(а) | G10: ВН-39-К5(а) | H10: ВН-40-К5(а)
A11: 48 | B11: ВН-29-К5(а) | C11: ВН-30-К5(а) | D11: ВН-31-К5(а) | E11: ВН-32-К5(а) | F11: ВН-31-К5(а) | G11: ВН-33-К5(а) | H11: ВН-34-К5(а)
A12: 47 | B12: ВН-35-К5(а) | C12: ВН-36-К5(а) | D12: ВН-37-К5(а) | E12: ВН-38-К5(а) | F12: ВН-37-К5(а) | G12: ВН-39-К5(а) | H12: ВН-40-К5(а)
A13: 46 | B13: ВН-29-К5(а) | C13: ВН-30-К5(а) | D13: ВН-31-К5(а) | E13: ВН-32-К5(а) | F13: ВН-31-К5(а) | G13: ВН-33-К5(а) | H13: ВН-34-К5(а)
A14: 45 | B14: ВН-35-К5(а) | C14: ВН-36-К5(а) | D14: ВН-37-К5(а) | E14: ВН-38-К5(а) | F14: ВН-37-К5(а) | G14: ВН-39-К5(а) | H14: ВН-40-К5(а)
... A18: 41 | B18: ВН-35-К5(а) | C18: ВН-36-К5(а) | D18: ВН-37-К5(а) | E18: ВН-38-К5(а) | F18: ВН-37-К5(а) | G18: ВН-39-К5(а) | H18: ВН-40-К5(а)
A19: 40 | B19: ВН-47-К5(а) | C19: ВН-48-К5(а) | D19: ВН-49-К5(а) | E19: ВН-50-К5(а) -к1 | F19: ВН-49-К5(а) | G19: ВН-51-К5(а) | H19: ВН-52-К5(а) | J19: =_xlfn.CONCAT(B19,", ",C19,", ",D19,", ",E19,", ", F19,", ",G19,", ",H19) -> ВН-47-К5(а), ВН-48-К5(а), ВН-49-К5(а), ВН-50-К5(а) -к1, ВН-49-К5(а), ВН-51-К5(а), ВН-52-К5(а)
A20: 39 | B20: ВН-41-К5(а) | C20: ВН-42-К5(а) | D20: ВН-43-К5(а) | E20: ВН-44-К5(а) | F20: ВН-43-К5(а) | G20: ВН-45-К5(а) | H20: ВН-46-К5(а)
A21: 38 | B21: ВН-29-К5(а) | C21: ВН-30-К5(а) | D21: ВН-31-К5(а) | E21: ВН-32-К5(а) | F21: ВН-31-К5(а) | G21: ВН-33-К5(а) | H21: ВН-34-К5(а)
A22: 37 | B22: ВН-35-К5(а) | C22: ВН-36-К5(а) | D22: ВН-37-К5(а) | E22: ВН-38-К5(а) | F22: ВН-37-К5(а) | G22: ВН-39-К5(а) | H22: ВН-40-К5(а)
A23: 36 | B23: ВН-29-К5(а) | C23: ВН-30-К5(а) | D23: ВН-31-К5(а) | E23: ВН-32-К5(а) | F23: ВН-31-К5(а) | G23: ВН-33-К5(а) | H23: ВН-34-К5(а)
A24: 35 | B24: ВН-35-К5(а) | C24: ВН-36-К5(а) | D24: ВН-37-К5(а) | E24: ВН-38-К5(а) | F24: ВН-37-К5(а) | G24: ВН-39-К5(а) | H24: ВН-40-К5(а)
A25: 34 | B25: ВН-29-К5(а) | C25: ВН-30-К5(а) | D25: ВН-31-К5(а) | E25: ВН-32-К5(а) | F25: ВН-31-К5(а) | G25: ВН-33-К5(а) | H25: ВН-34-К5(а)
A26: 33 | B26: ВН-35-К5(а) | C26: ВН-36-К5(а) | D26: ВН-37-К5(а) | E26: ВН-38-К5(а) | F26: ВН-37-К5(а) | G26: ВН-39-К5(а) | H26: ВН-40-К5(а)
A27: 32 | B27: ВН-29-К5(а) | C27: ВН-30-К5(а) | D27: ВН-31-К5(а) | E27: ВН-32-К5(а) | F27: ВН-31-К5(а) | G27: ВН-33-К5(а) | H27: ВН-34-К5(а)
A28: 31 | B28: ВН-35-К5(а) | C28: ВН-36-К5(а) | D28: ВН-37-К5(а) | E28: ВН-38-К5(а) | F28: ВН-37-К5(а) | G28: ВН-39-К5(а) | H28: ВН-40-К5(а)
A29: 30 | B29: ВН-29-К5(а) | C29: ВН-30-К5(а) | D29: ВН-31-К5(а) | E29: ВН-32-К5(а) | F29: ВН-31-К5(а) | G29: ВН-33-К5(а) | H29: ВН-34-К5(а)
A30: 29 | B30: ВН-35-К5(а) | C30: ВН-36-К5(а) | D30: ВН-37-К5(а) | E30: ВН-38-К5(а) | F30: ВН-37-К5(а) | G30: ВН-39-К5(а) | H30: ВН-40-К5(а)
A31: 28 | B31: ВН-29-К5(а) | C31: ВН-30-К5(а) | D31: ВН-31-К5(а) | E31: ВН-32-К5(а) | F31: ВН-31-К5(а) | G31: ВН-33-К5(а) | H31: ВН-34-К5(а)
... A38: 21 | B38: ВН-35-К5(а) | C38: ВН-36-К5(а) | D38: ВН-37-К5(а) | E38: ВН-38-К5(а) | F38: ВН-37-К5(а) | G38: ВН-39-К5(а) | H38: ВН-40-К5(а)
A39: 20 | B39: ВН-47-К5(а) | C39: ВН-48-К5(а) | D39: ВН-49-К5(а) | E39: ВН-50-К5(а) | F39: ВН-49-К5(а) | G39: ВН-51-К5(а) | H39: ВН-52-К5(а) | J39: =_xlfn.CONCAT(B39,", ",C39,", ",D39,", ",E39,", ", F39,", ",G39,", ",H39) -> ВН-47-К5(а), ВН-48-К5(а), ВН-49-К5(а), ВН-50-К5(а), ВН-49-К5(а), ВН-51-К5(а), ВН-52-К5(а)
A40: 19 | B40: ВН-41-К5(а) | C40: ВН-42-К5(а) | D40: ВН-43-К5(а) | E40: ВН-44-К5(а) | F40: ВН-43-К5(а) | G40: ВН-45-К5(а) | H40: ВН-46-К5(а) | J40: =_xlfn.CONCAT(B40,", ",C40,", ",D40,", ",E40,", ", F40,", ",G40,", ",H40) -> ВН-41-К5(а), ВН-42-К5(а), ВН-43-К5(а), ВН-44-К5(а), ВН-43-К5(а), ВН-45-К5(а), ВН-46-К5(а)
A41: 18 | B41: ВН-29-К5(а) | C41: ВН-30-К5(а) | D41: ВН-31-К5(а) | E41: ВН-32-К5(а) | F41: ВН-31-К5(а) | G41: ВН-33-К5(а) | H41: ВН-34-К5(а)
A42: 17 | B42: ВН-35-К5(а) | C42: ВН-36-К5(а) | D42: ВН-37-К5(а) | E42: ВН-38-К5(а) | F42: ВН-37-К5(а) | G42: ВН-39-К5(а) | H42: ВН-40-К5(а)
A43: 16 | B43: ВН-29-К5(а) | C43: ВН-30-К5(а) | D43: ВН-31-К5(а) | E43: ВН-32-К5(а) | F43: ВН-31-К5(а) | G43: ВН-33-К5(а) | H43: ВН-34-К5(а)
A44: 15 | B44: ВН-35-К5(а) | C44: ВН-36-К5(а) | D44: ВН-37-К5(а) | E44: ВН-38-К5(а) | F44: ВН-37-К5(а) | G44: ВН-39-К5(а) | H44: ВН-40-К5(а)
A45: 14 | B45: ВН-29-К5(а) | C45: ВН-30-К5(а) | D45: ВН-31-К5(а) | E45: ВН-32-К5(а) | F45: ВН-31-К5(а) | G45: ВН-33-К5(а) | H45: ВН-34-К5(а)
A46: 13 | B46: ВН-35-К5(а) | C46: ВН-36-К5(а) | D46: ВН-37-К5(а) | E46: ВН-38-К5(а) | F46: ВН-37-К5(а) | G46: ВН-39-К5(а) | H46: ВН-40-К5(а)
A47: 12 | B47: ВН-29-К5(а) | C47: ВН-30-К5(а) | D47: ВН-31-К5(а) | E47: ВН-32-К5(а) | F47: ВН-31-К5(а) | G47: ВН-33-К5(а) | H47: ВН-34-К5(а)
A48: 11 | B48: ВН-35-К5(а) | C48: ВН-36-К5(а) | D48: ВН-37-К5(а) | E48: ВН-38-К5(а) | F48: ВН-37-К5(а) | G48: ВН-39-К5(а) | H48: ВН-40-К5(а)
A49: 10 | B49: ВН-29-К5(а) | C49: ВН-30-К5(а) | D49: ВН-31-К5(а) | E49: ВН-32-К5(а) | F49: ВН-31-К5(а) | G49: ВН-33-К5(а) | H49: ВН-34-К5(а)
...

Sheet Размещение изделий на этажах1
A1: Этаж | B1: Этажи с сопадающим набором устанавливаемых изделий | C1: Изделия | D1: Кол-во этажей
A2: 2 | B2: 2 | C2: =Изделия1!J57 -> ВН-25-К5(а)-1, ВН-26-К5(а)-1, ВН-27-К5(а), ВН-28-К5(а), ВН-27-К5(а), ВН-26-К5(а)-2, ВН-25-К5(а)-2 | D2: 1
A3: 3 | B3: нечётные 3,5,…,17,21,…,37,41,…,55 | C3: =Изделия1!J56 -> ВН-35-К5(а), ВН-36-К5(а), ВН-37-К5(а), ВН-38-К5(а), ВН-37-К5(а), ВН-39-К5(а), ВН-40-К5(а) | D3: 25
A4: 4 | B4: чётные 4,6,…,18,22,…,38,42,…,56 | C4: =Изделия1!J55 -> ВН-29-К5(а), ВН-30-К5(а), ВН-31-К5(а), ВН-32-К5(а), ВН-31-К5(а), ВН-33-К5(а), ВН-34-К5(а) | D4: 25
A5: 19 | B5: 19,39 | C5: =Изделия1!J40 -> ВН-41-К5(а), ВН-42-К5(а), ВН-43-К5(а), ВН-44-К5(а), ВН-43-К5(а), ВН-45-К5(а), ВН-46-К5(а) | D5: 2
A6: 20 | B6: 20 | C6: =Изделия1!J39 -> ВН-47-К5(а), ВН-48-К5(а), ВН-49-К5(а), ВН-50-К5(а), ВН-49-К5(а), ВН-51-К5(а), ВН-52-К5(а) | D6: 1
A7: 40 | B7: 40 | C7: =Изделия1!J19 -> ВН-47-К5(а), ВН-48-К5(а), ВН-49-К5(а), ВН-50-К5(а) -к1, ВН-49-К5(а), ВН-51-К5(а), ВН-52-К5(а) | D7: 1
A8: 57 | B8: 57 | C8: =Изделия1!J2 -> ВН-53-К5(а), ВН-54-К5(а), ВН-55-К5(а), ВН-56-К5(а), ВН-55-К5(а), ВН-57-К5(а), ВН-58-К5(а) | D8: 1

Sheet Подсчёт изделий1
A1: РядИзделий | B1: Этаж | C1: Изделие | D1: Количество
A2: 1 | B2: =Изделия1!A2 -> 57 | C2: =Изделия1!B2 -> ВН-53-К5(а) | D2: 1
A3: 1 | B3: =Изделия1!A3 -> 56 | C3: =Изделия1!B3 -> ВН-29-К5(а) | D3: 1
A4: 1 | B4: =Изделия1!A4 -> 55 | C4: =Изделия1!B4 -> ВН-35-К5(а) | D4: 1
A5: 1 | B5: =Изделия1!A5 -> 54 | C5: =Изделия1!B5 -> ВН-29-К5(а) | D5: 1
A6: 1 | B6: =Изделия1!A6 -> 53 | C6: =Изделия1!B6 -> ВН-35-К5(а) | D6: 1
A7: 1 | B7: =Изделия1!A7 -> 52 | C7: =Изделия1!B7 -> ВН-29-К5(а) | D7: 1
A8: 1 | B8: =Изделия1!A8 -> 51 | C8: =Изделия1!B8 -> ВН-35-К5(а) | D8: 1
A9: 1 | B9: =Изделия1!A9 -> 50 | C9: =Изделия1!B9 -> ВН-29-К5(а) | D9: 1
A10: 1 | B10: =Изделия1!A10 -> 49 | C10: =Изделия1!B10 -> ВН-35-К5(а) | D10: 1
A11: 1 | B11: =Изделия1!A11 -> 48 | C11: =Изделия1!B11 -> ВН-29-К5(а) | D11: 1
A12: 1 | B12: =Изделия1!A12 -> 47 | C12: =Изделия1!B12 -> ВН-35-К5(а) | D12: 1
A13: 1 | B13: =Изделия1!A13 -> 46 | C13: =Изделия1!B13 -> ВН-29-К5(а) | D13: 1
... A57: 1 | B57: =Изделия1!A57 -> 2 | C57: =Изделия1!B57 -> ВН-25-К5(а)-1 | D57: 1
A58: 2 | B58: =Изделия1!A2 -> 57 | C58: =Изделия1!C2 -> ВН-54-К5(а) | D58: 1
A59: 2 | B59: =Изделия1!A3 -> 56 | C59: =Изделия1!C3 -> ВН-30-К5(а) | D59: 1
A60: 2 | B60: =Изделия1!A4 -> 55 | C60: =Изделия1!C4 -> ВН-36-К5(а) | D60: 1
A61: 2 | B61: =Изделия1!A5 -> 54 | C61: =Изделия1!C5 -> ВН-30-К5(а) | D61: 1
A62: 2 | B62: =Изделия1!A6 -> 53 | C62: =Изделия1!C6 -> ВН-36-К5(а) | D62: 1
A63: 2 | B63: =Изделия1!A7 -> 52 | C63: =Изделия1!C7 -> ВН-30-К5(а) | D63: 1
A64: 2 | B64: =Изделия1!A8 -> 51 | C64: =Изделия1!C8 -> ВН-36-К5(а) | D64: 1
A65: 2 | B65: =Изделия1!A9 -> 50 | C65: =Изделия1!C9 -> ВН-30-К5(а) | D65: 1
A66: 2 | B66: =Изделия1!A10 -> 49 | C66: =Изделия1!C10 -> ВН-36-К5(а) | D66: 1
A67: 2 | B67: =Изделия1!A11 -> 48 | C67: =Изделия1!C11 -> ВН-30-К5(а) | D67: 1
A68: 2 | B68: =Изделия1!A12 -> 47 | C68: =Изделия1!C12 -> ВН-36-К5(а) | D68: 1
A69: 2 | B69: =Изделия1!A13 -> 46 | C69: =Изделия1!C13 -> ВН-30-К5(а) | D69: 1
... A113: 2 | B113: =Изделия1!A57 -> 2 | C113: =Изделия1!C57 -> ВН-26-К5(а)-1 | D113: 1
A114: 3 | B114: =Изделия1!A2 -> 57 | C114: =Изделия1!D2 -> ВН-55-К5(а) | D114: 1
A115: 3 | B115: =Изделия1!A3 -> 56 | C115: =Изделия1!D3 -> ВН-31-К5(а) | D115: 1
A116: 3 | B116: =Изделия1!A4 -> 55 | C116: =Изделия1!D4 -> ВН-37-К5(а) | D116: 1
A117: 3 | B117: =Изделия1!A5 -> 54 | C117: =Изделия1!D5 -> ВН-31-К5(а) | D117: 1
A118: 3 | B118: =Изделия1!A6 -> 53 | C118: =Изделия1!D6 -> ВН-37-К5(а) | D118: 1
A119: 3 | B119: =Изделия1!A7 -> 52 | C119: =Изделия1!D7 -> ВН-31-К5(а) | D119: 1
A120: 3 | B120: =Изделия1!A8 -> 51 | C120: =Изделия1!D8 -> ВН-37-К5(а) | D120: 1
A121: 3 | B121: =Изделия1!A9 -> 50 | C121: =Изделия1!D9 -> ВН-31-К5(а) | D121: 1
A122: 3 | B122: =Изделия1!A10 -> 49 | C122: =Изделия1!D10 -> ВН-37-К5(а) | D122: 1
A123: 3 | B123: =Изделия1!A11 -> 48 | C123: =Изделия1!D11 -> ВН-31-К5(а) | D123: 1
A124: 3 | B124: =Изделия1!A12 -> 47 | C124: =Изделия1!D12 -> ВН-37-К5(а) | D124: 1
A125: 3 | B125: =Изделия1!A13 -> 46 | C125: =Изделия1!D13 -> ВН-31-К5(а) | D125: 1
... A169: 3 | B169: =Изделия1!A57 -> 2 | C169: =Изделия1!D57 -> ВН-27-К5(а) | D169: 1
...

Sheet Сводная таблица_Подсчёт изделий
A1: Изделие | B1: Сумма - Количество
A2: ВН-50-К5(а) -к1 | B2: 1
A3: ВН-25-К5(а)-1 | B3: 1
A4: ВН-25-К5(а)-2 | B4: 1
A5: ВН-26-К5(а)-1 | B5: 1
A6: ВН-26-К5(а)-2 | B6: 1
A7: ВН-27-К5(а) | B7: 2
A8: ВН-28-К5(а) | B8: 1
A9: ВН-29-К5(а) | B9: 25
A10: ВН-30-К5(а) | B10: 25
A11: ВН-31-К5(а) | B11: 50
A12: ВН-32-К5(а) | B12: 25
A13: ВН-33-К5(а) | B13: 25
... A39: Итог Результат | B39: 392

Sheet Data
B1: Заполнения | D1: ТипРядовЗаполнений | F1: ТипКреплений | H1: Подпорки | J1: Опоры | L1: Термомосты | N1: Крепление ригеля | P1: Подставка | R1: Опоры | T1: Ряды опор
B2: 1а | D2: Зап1 | F2: Креп1 | H2: Подпорка1 | J2: о1 | L2: т0 | N2: с1 | P2: Подставка | R2: о1лев | T2: ОпораМ
B3: 1б | D3: Зап1_20 | F3: Креп1_20 | H3: Подпорка1_20 | J3: о1лев | L3: тСтойка | N3: с2 | R3: о1прав | T3: ОпораМ_Ус
B4: 3а | D4: Зап2 | F4: Креп2 | H4: Подпорка2 | J4: о1прав | L4: т13 | N4: с3 | R4: о1 | T4: Опора1
B5: 3б | D5: Зап2_57 | F5: Креп2_57 | H5: Подпорка2_57 | J5: о1ц | L5: т24 | N5: с4 | R5: о2лев | T5: Опора1_20
B6: 5а | D6: Межэтажка | F6: КрепМ | J6: о2 | L6: т1 | N6: с2ус | R6: о2прав | T6: Опора1_40
B7: 5б | D7: Базовый | F7: КрепМ_Ус | H7: пл2_Подпорка1 | J7: о2лев | L7: т2 | N7: с6 | R7: о2
B8: 6а | D8: ЗапНизВерх | H8: пл2_Подпорка2 | J8: о2прав | L8: т3 | N8: с7 | T8: Опора2
B9: 6б | D9: Термомост | H9: пл2_Подпорка2_57 | J9: о3 | L9: т4 | N9: с80 | T9: Опора2_57
B10: Тип 8 | D10: пл2_Зап1 | F10: пл2_Креп1 | J10: о3лев
B11: 7б | D11: пл2_Зап2 | F11: пл2_Креп2 | J11: о3прав
B12: Тип 10 | D12: пл2_Зап2_57 | F12: пл2_КрепМ | J12: о4
B13: ВС | D13: пл2_Межэтажка | F13: пл2_КрепМУс | J13: о5
B14: СН | D14: пл2_Базовый
B15: Лист 2 мм | D15: пл2_ЗапНизВерх | F15: ВС
B16: Лист 1 мм
B17: Продлить | D17: ВС
B18: НВС | D18: ххх
