Workbook

Sheet РядыСтоек3
B1: Плоскость | C1: тип | D1: стойка | E1: поЦентрам | F1: Установка | G1: ДопСтойка
B2: (5-А)-(5-Л) | C2: 2 | D2: 1 | E2: 0 | F2: =E2 -> 0
B3: (5-А)-(5-Л) | C3: 2 | D3: 2 | E3: =700+560 -> 1260 | F3: =F2+E3 -> 1260
B4: (5-А)-(5-Л) | C4: 2 | D4: 3 | E4: 600 | F4: =F3+E4 -> 1860
B5: (5-А)-(5-Л) | C5: 2 | D5: 4 | E5: 1430 | F5: =F4+E5 -> 3290
B6: (5-А)-(5-Л) | C6: 2 | D6: 5 | E6: 1770 | F6: =F5+E6 -> 5060 | G6: 1
B7: (5-А)-(5-Л) | C7: 2 | D7: 6 | E7: 600 | F7: =F6+E7 -> 5660
B8: (5-А)-(5-Л) | C8: 2 | D8: 7 | E8: 1330 | F8: =F7+E8 -> 6990 | H8: 5-Б
B9: (5-А)-(5-Л) | C9: 2 | D9: 8 | E9: 1470 | F9: =F8+E9 -> 8460 | G9: 1
B10: (5-А)-(5-Л) | C10: 2 | D10: 9 | E10: 600 | F10: =F9+E10 -> 9060
B11: (5-А)-(5-Л) | C11: 2 | D11: 10 | E11: 1330 | F11: =F10+E11 -> 10390
B12: (5-А)-(5-Л) | C12: 2 | D12: 11 | E12: 1470 | F12: =F11+E12 -> 11860 | G12: 1
B13: (5-А)-(5-Л) | C13: 2 | D13: 12 | E13: 600 | F13: =F12+E13 -> 12460
B14: (5-А)-(5-Л) | C14: 2 | D14: 13 | E14: 1330 | F14: =F13+E14 -> 13790 | H14: 5-В
B15: (5-А)-(5-Л) | C15: 2 | D15: 14 | E15: 2550 | F15: =F14+E15 -> 16340 | G15: 1 | H15: 5-Г
B16: (5-А)-(5-Л) | C16: 2 | D16: 15 | E16: 600 | F16: =F15+E16 -> 16940
B17: (5-А)-(5-Л) | C17: 2 | D17: 16 | E17: 1350 | F17: =F16+E17 -> 18290
B18: (5-А)-(5-Л) | C18: 2 | D18: 17 | E18: 1770 | F18: =F17+E18 -> 20060 | G18: 1
B19: (5-А)-(5-Л) | C19: 2 | D19: 18 | E19: 600 | F19: =F18+E19 -> 20660
B20: (5-А)-(5-Л) | C20: 2 | D20: 19 | E20: 1580 | F20: =F19+E20 -> 22240 | H20: 5-Д
B21: (5-А)-(5-Л) | C21: 2 | D21: 20 | E21: 1020 | F21: =F20+E21 -> 23260 | G21: 1
B22: (5-А)-(5-Л) | C22: 2 | D22: 21 | E22: 600 | F22: =F21+E22 -> 23860
B23: (5-А)-(5-Л) | C23: 2 | D23: 22 | E23: 1480 | F23: =F22+E23 -> 25340
B24: (5-А)-(5-Л) | C24: 2 | D24: 23 | E24: 1470 | F24: =F23+E24 -> 26810 | H24: 5-Е
B25: (5-А)-(5-Л) | C25: 2 | D25: 24 | E25: 1330 | F25: =F24+E25 -> 28140
B26: (5-А)-(5-Л) | C26: 2 | D26: 25 | E26: 1020 | F26: =F25+E26 -> 29160 | G26: 1 | H26: 5-Ж
B27: (5-А)-(5-Л) | C27: 2 | D27: 26 | E27: 600 | F27: =F26+E27 -> 29760
B28: (5-А)-(5-Л) | C28: 2 | D28: 27 | E28: 1340 | F28: =F27+E28 -> 31100
B29: (5-А)-(5-Л) | C29: 2 | D29: 28 | E29: 2550 | F29: =F28+E29 -> 33650 | G29: 1 | H29: 5-И
B30: (5-А)-(5-Л) | C30: 2 | D30: 29 | E30: 600 | F30: =F29+E30 -> 34250
B31: (5-А)-(5-Л) | C31: 2 | D31: 30 | E31: 1340 | F31: =F30+E31 -> 35590 | H31: 5-К
B32: (5-А)-(5-Л) | C32: 2 | D32: 31 | E32: 1770 | F32: =F31+E32 -> 37360 | G32: 1
B33: (5-А)-(5-Л) | C33: 2 | D33: 32 | E33: 600 | F33: =F32+E33 -> 37960
B34: (5-А)-(5-Л) | C34: 2 | D34: 33 | E34: 1340 | F34: =F33+E34 -> 39300
B35: (5-А)-(5-Л) | C35: 2 | D35: 34 | E35: 600 | F35: =F34+E35 -> 39900
B36: (5-А)-(5-Л) | C36: 2 | D36: 35 | E36: =1000+700 -> 1700 | F36: =F35+E36 -> 41600 | I36: =SUM(E2:E36) -> 41600 | J36: чертёж | K36: 41600
B37: (5-А)-(5-Л) | C37: 3 | D37: 1 | E37: 0 | F37: =E37 -> 0 | I37: 0
B38: (5-А)-(5-Л) | C38: 3 | D38: 2 | E38: =700+560 -> 1260 | F38: =F37+E38 -> 1260
B39: (5-А)-(5-Л) | C39: 3 | D39: 3 | E39: 600 | F39: =F38+E39 -> 1860
B40: (5-А)-(5-Л) | C40: 3 | D40: 4 | E40: 1430 | F40: =F39+E40 -> 3290
...

Sheet РядыЗаполнений3
A1: Стойка | B1: Зап2 | C1: Зап30 | D1: Зап3 | E1: Зап29 | F1: Зап57 | G1: ЗапНизВерх
A2: 0 | G2: Лист 2 мм
A3: 1 | B3: 5а | C3: 5б | D3: 5а | E3: 5б | F3: 5б | G3: Лист 2 мм
A4: 2 | B4: ОК-1 | C4: ОК-1.1 | D4: ОК-1 | E4: ОК-1.1 | F4: ОК-1.1 | G4: Лист 2 мм
A5: 3 | B5: Тип 10 | C5: Тип 10 | D5: Тип 10 | E5: Тип 10 | F5: Тип 10 | G5: Лист 2 мм
A6: 4 | B6: 3а | C6: 3б | D6: ОК-1 | E6: ОК-1.1 | F6: ОК-1.1 | G6: Лист 2 мм
A7: 5 | B7: ОК-1 | C7: ОК-1.1 | D7: 3а | E7: 3б | F7: 3б | G7: Лист 2 мм
A8: 6 | B8: Тип 10 | C8: Тип 10 | D8: Тип 10 | E8: Тип 10 | F8: Тип 10 | G8: Лист 2 мм
A9: 7 | B9: 5а | C9: 5б | D9: ОК-1 | E9: ОК-1.1 | F9: ОК-1.1 | G9: Лист 2 мм
A10: 8 | B10: ОК-1 | C10: ОК-1.1 | D10: 5а | E10: 5б | F10: 5б | G10: Лист 2 мм
A11: 9 | B11: Тип 10 | C11: Тип 10 | D11: Тип 10 | E11: Тип 10 | F11: Тип 10 | G11: Лист 2 мм
A12: 10 | B12: 5а | C12: 5б | D12: ОК-1 | E12: ОК-1.1 | F12: ОК-1.1 | G12: Лист 2 мм
A13: 11 | B13: ОК-1 | C13: ОК-1.1 | D13: 5а | E13: 5б | F13: 5б | G13: Лист 2 мм
A14: 12 | B14: Тип 10 | C14: Тип 10 | D14: Тип 10 | E14: Тип 10 | F14: Тип 10 | G14: Лист 2 мм
... A36: 34 | B36: 3а | C36: 3б | D36: 3а | E36: 3б | F36: 3б | G36: Лист 2 мм
A37: 35 | G37: Лист 2 мм

Sheet РядыКреплений3
A1: Зап2 | B1: Зап3 | C1: Стойка | D1: Креп2 | E1: Креп3 | F1: КрепВерх | G1: Подпорка2 | H1: Подпорка3
C2: 0
A3: 5а | B3: 5а | C3: 1 | D3: с2 | E3: с2 | F3: с2 | G3: 700 | H3: 700
A4: 6а2 | B4: ВС | C4: 2 | D4: с2 | E4: с2 | F4: с2
A5: Тип 10 | B5: Тип 10 | C5: 3 | D5: с2 | E5: с2 | F5: с2
A6: 3а | B6: ВС | C6: 4 | D6: с3 | E6: с2 | F6: с2
A7: 6а2 | B7: 3а | C7: 5 | D7: с2 | E7: с3 | F7: с2
A8: Тип 10 | B8: Тип 10 | C8: 6 | D8: с2 | E8: с2 | F8: с2
A9: 5а | B9: ВС | C9: 7 | D9: с2 | E9: с2 | F9: с2
A10: 6а2 | B10: 5а | C10: 8 | D10: с2 | E10: с2 | F10: с2
A11: Тип 10 | B11: Тип 10 | C11: 9 | D11: с2 | E11: с2 | F11: с2
A12: 5а | B12: ВС | C12: 10 | D12: с2 | E12: с2 | F12: с2
A13: 6а2 | B13: 5а | C13: 11 | D13: с2 | E13: с2 | F13: с2
A14: Тип 10 | B14: Тип 10 | C14: 12 | D14: с2 | E14: с2 | F14: с2
A15: 3а | B15: ВС | C15: 13 | D15: с3 | E15: с2 | F15: с2 | G15: 1575
A16: 6а2 | B16: 3а | C16: 14 | D16: с2 | E16: с3 | F16: с2 | H16: 1575
A17: Тип 10 | B17: Тип 10 | C17: 15 | D17: с2 | E17: с2 | F17: с2
A18: 3а | B18: ВС | C18: 16 | D18: с3 | E18: с2 | F18: с2
A19: 6а2 | B19: 3а | C19: 17 | D19: с2 | E19: с3 | F19: с2
A20: Тип 10 | B20: Тип 10 | C20: 18 | D20: с2 | E20: с2 | F20: с2
A21: 6а | B21: ВС | C21: 19 | D21: с2 | E21: с2 | F21: с2
A22: 6а2 | B22: 6а | C22: 20 | D22: с2 | E22: с2 | F22: с2
A23: Тип 10 | B23: Тип 10 | C23: 21 | D23: с2 | E23: с2 | F23: с2
A24: 5а | B24: 5а | C24: 22 | D24: с2 | E24: с2 | F24: с2
A25: Тип 10 | B25: Тип 10 | C25: 23 | D25: с2 | E25: с2 | F25: с2
A26: 6а | B26: ВС | C26: 24 | D26: с2 | E26: с2 | F26: с2
A27: 6а2 | B27: 6а | C27: 25 | D27: с2 | E27: с2 | F27: с2
A28: Тип 10 | B28: Тип 10 | C28: 26 | D28: с2 | E28: с2 | F28: с2
A29: 3а | B29: ВС | C29: 27 | D29: с3 | E29: с2 | F29: с2 | G29: 1275
A30: 6а2 | B30: 3а | C30: 28 | D30: с2 | E30: с3 | F30: с2 | H30: 1275
A31: Тип 10 | B31: Тип 10 | C31: 29 | D31: с2 | E31: с2 | F31: с2
A32: 3а | B32: ВС | C32: 30 | D32: с3 | E32: с2 | F32: с2
A33: 6а2 | B33: 3а | C33: 31 | D33: с2 | E33: с3 | F33: с2
A34: Тип 10 | B34: Тип 10 | C34: 32 | D34: с2 | E34: с2 | F34: с2
A35: 6а2 | B35: ВС | C35: 33 | D35: с2 | E35: с2 | F35: с2
A36: 3а | B36: 3а | C36: 34 | D36: с3 | E36: с3 | F36: с2 | G36: 1000 | H36: 1000

Sheet РядыОпор3
A1: Зап2 | B1: Креп2 | C1: Креп3 | D1: Стойка | E1: Опора2 | F1: Опора30 | G1: Опора3 | H1: Опора29 | I1: Опора57
D2: 0
A3: 5а | B3: с2 | C3: с2 | D3: 1 | E3: о2прав | F3: о2прав | G3: о2прав | H3: о2прав | I3: о2прав
A4: 6а2 | B4: с2 | C4: с2 | D4: 2 | E4: о1 | F4: о1 | G4: о1 | H4: о1 | I4: о1
A5: Тип 10 | B5: с2 | C5: с2 | D5: 3 | E5: о1 | F5: о1 | G5: о1 | H5: о1 | I5: о1
A6: 3а | B6: с3 | C6: с2 | D6: 4 | E6: о3 | F6: о2 | G6: о1 | H6: о1 | I6: о1
A7: 6а2 | B7: с2 | C7: с3 | D7: 5 | E7: о1 | F7: о1 | G7: о3 | H7: о2 | I7: о3
A8: Тип 10 | B8: с2 | C8: с2 | D8: 6 | E8: о1 | F8: о1 | G8: о1 | H8: о1 | I8: о1
A9: 5а | B9: с2 | C9: с2 | D9: 7 | E9: о2 | F9: о2 | G9: о1 | H9: о1 | I9: о1
A10: 6а2 | B10: с2 | C10: с2 | D10: 8 | E10: о1 | F10: о1 | G10: о2 | H10: о2 | I10: о2
A11: Тип 10 | B11: с2 | C11: с2 | D11: 9 | E11: о1 | F11: о1 | G11: о1 | H11: о1 | I11: о1
A12: 5а | B12: с2 | C12: с2 | D12: 10 | E12: о2 | F12: о2 | G12: о1 | H12: о1 | I12: о1
A13: 6а2 | B13: с2 | C13: с2 | D13: 11 | E13: о1 | F13: о1 | G13: о2 | H13: о2 | I13: о2
A14: Тип 10 | B14: с2 | C14: с2 | D14: 12 | E14: о1 | F14: о1 | G14: о1 | H14: о1 | I14: о1
A15: 3а | B15: с3 | C15: с2 | D15: 13 | E15: о3 | F15: о3 | G15: о1 | H15: о1 | I15: о1лев | K15: с правой стороны продолжение опоры о4
A16: 6а2 | B16: с2 | C16: с3 | D16: 14 | E16: о1 | F16: о1 | G16: о3 | H16: о3 | I16: о4
A17: Тип 10 | B17: с2 | C17: с2 | D17: 15 | E17: о1 | F17: о1 | G17: о1 | H17: о1 | I17: о1прав
A18: 3а | B18: с3 | C18: с2 | D18: 16 | E18: о3 | F18: о2 | G18: о1 | H18: о1 | I18: о1
A19: 6а2 | B19: с2 | C19: с3 | D19: 17 | E19: о1 | F19: о1 | G19: о3 | H19: о2 | I19: о3
A20: Тип 10 | B20: с2 | C20: с2 | D20: 18 | E20: о1 | F20: о1 | G20: о1 | H20: о1 | I20: о2
A21: 6а | B21: с2 | C21: с2 | D21: 19 | E21: о1 | F21: о1 | G21: о1 | H21: о1 | I21: о1
A22: 6а2 | B22: с2 | C22: с2 | D22: 20 | E22: о1 | F22: о1 | G22: о1 | H22: о1 | I22: о1
A23: Тип 10 | B23: с2 | C23: с2 | D23: 21 | E23: о1 | F23: о1 | G23: о1 | H23: о1 | I23: о1
A24: 5а | B24: с2 | C24: с2 | D24: 22 | E24: о2 | F24: о2 | G24: о2 | H24: о2 | I24: о2
A25: Тип 10 | B25: с2 | C25: с2 | D25: 23 | E25: о1 | F25: о1 | G25: о1 | H25: о1 | I25: о1
A26: 6а | B26: с2 | C26: с2 | D26: 24 | E26: о1 | F26: о1 | G26: о1 | H26: о1 | I26: о1
A27: 6а2 | B27: с2 | C27: с2 | D27: 25 | E27: о1 | F27: о1 | G27: о1 | H27: о1 | I27: о1
A28: Тип 10 | B28: с2 | C28: с2 | D28: 26 | E28: о1 | F28: о1 | G28: о1 | H28: о1 | I28: о1
A29: 3а | B29: с3 | C29: с2 | D29: 27 | E29: о3 | F29: о3 | G29: о1 | H29: о1 | I29: о1лев | K29: с правой стороны продолжение опоры о4
A30: 6а2 | B30: с2 | C30: с3 | D30: 28 | E30: о1 | F30: о1 | G30: о3 | H30: о3 | I30: о4
A31: Тип 10 | B31: с2 | C31: с2 | D31: 29 | E31: о1 | F31: о1 | G31: о1 | H31: о1 | I31: о1прав
A32: 3а | B32: с3 | C32: с2 | D32: 30 | E32: о3 | F32: о2 | G32: о1 | H32: о1 | I32: о1
A33: 6а2 | B33: с2 | C33: с3 | D33: 31 | E33: о1 | F33: о1 | G33: о3 | H33: о2 | I33: о3
A34: Тип 10 | B34: с2 | C34: с2 | D34: 32 | E34: о1 | F34: о1 | G34: о1 | H34: о1 | I34: о1
A35: 6а2 | B35: с2 | C35: с2 | D35: 33 | E35: о1 | F35: о1 | G35: о1 | H35: о1 | I35: о1
A36: 3а | B36: с3 | C36: с3 | D36: 34 | E36: о3лев | F36: о3лев | G36: о3лев | H36: о3лев | I36: о3лев

Sheet РядыРигелей3
A1: Этаж | B1: НизСтойки | C1: ВысотаСтойки | D1: Зазор | E1: РядИзделия | F1: РядФасада | G1: ПоЦентрам | H1: Установка | I1: ТипРядовСтоек | J1: ТипРядовЗаполнений | K1: ТипКреплений | L1: Подпорки | M1: Опоры | O1: Уровень ЧП | P1: Низ Окна | Q1: РучкаотНизаОкна
A2: 0 | B2: 0 | E2: 0 | F2: 0 | G2: 0 | H2: 0 | I2: 2 | J2: ЗапНизВерх
A3: 2 | B3: 8090 | C3: 3350 | D3: 10 | E3: 1 | F3: 1 | G3: 935 | H3: =G3+B3 -> 9025 | I3: 2 | J3: Зап2 | K3: Креп2 | L3: Подпорка2 | M3: Опора2 | O3: 8360
A4: 2 | E4: 2 | F4: 2 | G4: 2030 | H4: =H3+G4 -> 11055 | J4: ЗапНизВерх | K4: КрепВерх | S4: Этаж | T4: Ригель | U4: чп | V4: ОтЦентра | W4: низОкна
A5: 3 | B5: 11450 | C5: 3350 | D5: 10 | E5: 1 | F5: 3 | G5: 935 | H5: =G5+B5 -> 12385 | I5: 3 | J5: Зап3 | K5: Креп3 | L5: Подпорка3 | M5: Опора3 | O5: =O3+C3+D3 -> 11720 | S5: 19 | T5: 66455 | U5: 65480 | V5: 13 | W5: =T5-U5+V5 -> 988
A6: 3 | E6: 2 | F6: 4 | G6: 2030 | H6: =H5+G6 -> 14415 | J6: ЗапНизВерх | K6: КрепВерх | S6: 20 | T6: 69975 | U6: 69000 | V6: 13 | W6: =T6-U6+V6 -> 988
A7: =A5+1 -> 4 | B7: =B5+C5+D5 -> 14810 | C7: =$C$5 -> 3350 | D7: 10 | E7: =E5 -> 1 | F7: 5 | G7: =$G$5 -> 935 | H7: =G7+B7 -> 15745 | I7: 2 | J7: Зап2 | K7: Креп2 | L7: Подпорка2 | M7: Опора2 | O7: =O5+C5+D5 -> 15080
A8: =A6+1 -> 4 | E8: =E6 -> 2 | F8: 6 | G8: =$G$6 -> 2030 | H8: =H7+G8 -> 17775 | J8: ЗапНизВерх | K8: КрепВерх | S8: 39 | T8: 133815 | U8: 132840 | V8: 13 | W8: =T8-U8+V8 -> 988
A9: =A7+1 -> 5 | B9: =B7+C7+D7 -> 18170 | C9: =$C$5 -> 3350 | D9: 10 | E9: =E7 -> 1 | F9: 7 | G9: =$G$5 -> 935 | H9: =G9+B9 -> 19105 | I9: 3 | J9: Зап3 | K9: Креп3 | L9: Подпорка3 | M9: Опора3 | O9: =O7+C7+D7 -> 18440 | S9: 41 | T9: 140695 | U9: 139720 | V9: 13 | W9: =T9-U9+V9 -> 988
A10: =A8+1 -> 5 | E10: =E8 -> 2 | F10: 8 | G10: =$G$6 -> 2030 | H10: =H9+G10 -> 21135 | J10: ЗапНизВерх | K10: КрепВерх
A11: =A9+1 -> 6 | B11: =B9+C9+D9 -> 21530 | C11: =$C$5 -> 3350 | D11: 10 | E11: =E9 -> 1 | F11: 9 | G11: =$G$5 -> 935 | H11: =G11+B11 -> 22465 | I11: 2 | J11: Зап2 | K11: Креп2 | L11: Подпорка2 | M11: Опора2 | O11: =O9+C9+D9 -> 21800
A12: =A10+1 -> 6 | E12: =E10 -> 2 | F12: 10 | G12: =$G$6 -> 2030 | H12: =H11+G12 -> 24495 | J12: ЗапНизВерх | K12: КрепВерх
A13: =A11+1 -> 7 | B13: =B11+C11+D11 -> 24890 | C13: =$C$5 -> 3350 | D13: 10 | E13: =E11 -> 1 | F13: 11 | G13: =$G$5 -> 935 | H13: =G13+B13 -> 25825 | I13: 3 | J13: Зап3 | K13: Креп3 | L13: Подпорка3 | M13: Опора3 | O13: =O11+C11+D11 -> 25160
A14: =A12+1 -> 7 | E14: =E12 -> 2 | F14: 12 | G14: =$G$6 -> 2030 | H14: =H13+G14 -> 27855 | J14: ЗапНизВерх | K14: КрепВерх
A15: =A13+1 -> 8 | B15: =B13+C13+D13 -> 28250 | C15: =$C$5 -> 3350 | D15: 10 | E15: =E13 -> 1 | F15: 13 | G15: =$G$5 -> 935 | H15: =G15+B15 -> 29185 | I15: 2 | J15: Зап2 | K15: Креп2 | L15: Подпорка2 | M15: Опора2 | O15: =O13+C13+D13 -> 28520
A16: =A14+1 -> 8 | E16: =E14 -> 2 | F16: 14 | G16: =$G$6 -> 2030 | H16: =H15+G16 -> 31215 | J16: ЗапНизВерх | K16: КрепВерх
A17: =A15+1 -> 9 | B17: =B15+C15+D15 -> 31610 | C17: =$C$5 -> 3350 | D17: 10 | E17: =E15 -> 1 | F17: 15 | G17: =$G$5 -> 935 | H17: =G17+B17 -> 32545 | I17: 3 | J17: Зап3 | K17: Креп3 | L17: Подпорка3 | M17: Опора3 | O17: =O15+C15+D15 -> 31880
A18: =A16+1 -> 9 | E18: =E16 -> 2 | F18: 16 | G18: =$G$6 -> 2030 | H18: =H17+G18 -> 34575 | J18: ЗапНизВерх | K18: КрепВерх
A19: =A17+1 -> 10 | B19: =B17+C17+D17 -> 34970 | C19: =$C$5 -> 3350 | D19: 10 | E19: =E17 -> 1 | F19: 17 | G19: =$G$5 -> 935 | H19: =G19+B19 -> 35905 | I19: 2 | J19: Зап2 | K19: Креп2 | L19: Подпорка2 | M19: Опора2 | O19: =O17+C17+D17 -> 35240
A20: =A18+1 -> 10 | E20: =E18 -> 2 | F20: 18 | G20: =$G$6 -> 2030 | H20: =H19+G20 -> 37935 | J20: ЗапНизВерх | K20: КрепВерх
A21: =A19+1 -> 11 | B21: =B19+C19+D19 -> 38330 | C21: =$C$5 -> 3350 | D21: 10 | E21: =E19 -> 1 | F21: 19 | G21: =$G$5 -> 935 | H21: =G21+B21 -> 39265 | I21: 3 | J21: Зап3 | K21: Креп3 | L21: Подпорка3 | M21: Опора3 | O21: =O19+C19+D19 -> 38600
A22: =A20+1 -> 11 | E22: =E20 -> 2 | F22: 20 | G22: =$G$6 -> 2030 | H22: =H21+G22 -> 41295 | J22: ЗапНизВерх | K22: КрепВерх
A23: =A21+1 -> 12 | B23: =B21+C21+D21 -> 41690 | C23: =$C$5 -> 3350 | D23: 10 | E23: =E21 -> 1 | F23: 21 | G23: =$G$5 -> 935 | H23: =G23+B23 -> 42625 | I23: 2 | J23: Зап2 | K23: Креп2 | L23: Подпорка2 | M23: Опора2 | O23: =O21+C21+D21 -> 41960
A24: =A22+1 -> 12 | E24: =E22 -> 2 | F24: 22 | G24: =$G$6 -> 2030 | H24: =H23+G24 -> 44655 | J24: ЗапНизВерх | K24: КрепВерх
A25: =A23+1 -> 13 | B25: =B23+C23+D23 -> 45050 | C25: =$C$5 -> 3350 | D25: 10 | E25: =E23 -> 1 | F25: 23 | G25: =$G$5 -> 935 | H25: =G25+B25 -> 45985 | I25: 3 | J25: Зап3 | K25: Креп3 | L25: Подпорка3 | M25: Опора3 | O25: =O23+C23+D23 -> 45320
A26: =A24+1 -> 13 | E26: =E24 -> 2 | F26: 24 | G26: =$G$6 -> 2030 | H26: =H25+G26 -> 48015 | J26: ЗапНизВерх | K26: КрепВерх
A27: =A25+1 -> 14 | B27: =B25+C25+D25 -> 48410 | C27: =$C$5 -> 3350 | D27: 10 | E27: =E25 -> 1 | F27: 25 | G27: =$G$5 -> 935 | H27: =G27+B27 -> 49345 | I27: 2 | J27: Зап2 | K27: Креп2 | L27: Подпорка2 | M27: Опора2 | O27: =O25+C25+D25 -> 48680
A28: =A26+1 -> 14 | E28: =E26 -> 2 | F28: 26 | G28: =$G$6 -> 2030 | H28: =H27+G28 -> 51375 | J28: ЗапНизВерх | K28: КрепВерх
A29: =A27+1 -> 15 | B29: =B27+C27+D27 -> 51770 | C29: =$C$5 -> 3350 | D29: 10 | E29: =E27 -> 1 | F29: 27 | G29: =$G$5 -> 935 | H29: =G29+B29 -> 52705 | I29: 3 | J29: Зап3 | K29: Креп3 | L29: Подпорка3 | M29: Опора3 | O29: =O27+C27+D27 -> 52040
A30: =A28+1 -> 15 | E30: =E28 -> 2 | F30: 28 | G30: =$G$6 -> 2030 | H30: =H29+G30 -> 54735 | J30: ЗапНизВерх | K30: КрепВерх
A31: =A29+1 -> 16 | B31: =B29+C29+D29 -> 55130 | C31: =$C$5 -> 3350 | D31: 10 | E31: =E29 -> 1 | F31: 29 | G31: =$G$5 -> 935 | H31: =G31+B31 -> 56065 | I31: 2 | J31: Зап2 | K31: Креп2 | L31: Подпорка2 | M31: Опора2 | O31: =O29+C29+D29 -> 55400
A32: =A30+1 -> 16 | E32: =E30 -> 2 | F32: 30 | G32: =$G$6 -> 2030 | H32: =H31+G32 -> 58095 | J32: ЗапНизВерх | K32: КрепВерх
A33: =A31+1 -> 17 | B33: =B31+C31+D31 -> 58490 | C33: =$C$5 -> 3350 | D33: 10 | E33: =E31 -> 1 | F33: 31 | G33: =$G$5 -> 935 | H33: =G33+B33 -> 59425 | I33: 3 | J33: Зап3 | K33: Креп3 | L33: Подпорка3 | M33: Опора3 | O33: =O31+C31+D31 -> 58760
A34: =A32+1 -> 17 | E34: =E32 -> 2 | F34: 32 | G34: =$G$6 -> 2030 | H34: =H33+G34 -> 61455 | J34: ЗапНизВерх | K34: КрепВерх
A35: =A33+1 -> 18 | B35: =B33+C33+D33 -> 61850 | C35: =$C$5 -> 3350 | D35: 10 | E35: =E33 -> 1 | F35: 33 | G35: =$G$5 -> 935 | H35: =G35+B35 -> 62785 | I35: 2 | J35: Зап2 | K35: Креп2 | L35: Подпорка2 | M35: Опора2 | O35: =O33+C33+D33 -> 62120
A36: =A34+1 -> 18 | E36: =E34 -> 2 | F36: 34 | G36: =$G$6 -> 2030 | H36: =H35+G36 -> 64815 | J36: ЗапНизВерх | K36: КрепВерх
A37: =A35+1 -> 19 | B37: =B35+C35+D35 -> 65210 | C37: 3510 | D37: 10 | E37: =E35 -> 1 | F37: 35 | G37: =$G$5 -> 935 | H37: =G37+B37 -> 66145 | I37: 3 | J37: Зап3 | K37: Креп3 | L37: Подпорка3 | M37: Опора3 | O37: =O35+C35+D35 -> 65480
A38: =A36+1 -> 19 | E38: =E36 -> 2 | F38: 36 | G38: =$G$6 -> 2030 | H38: =H37+G38 -> 68175 | J38: ЗапНизВерх | K38: КрепВерх
A39: =A37+1 -> 20 | B39: =B37+C37+D37 -> 68730 | C39: 3350 | D39: 10 | E39: =E37 -> 1 | F39: 37 | G39: =$G$5 -> 935 | H39: =G39+B39 -> 69665 | I39: 2 | J39: Зап2 | K39: Креп2 | L39: Подпорка2 | M39: Опора2 | O39: =O37+C37+D37 -> 69000
A40: =A38+1 -> 20 | E40: =E38 -> 2 | F40: 38 | G40: =$G$6 -> 2030 | H40: =H39+G40 -> 71695 | J40: ЗапНизВерх | K40: КрепВерх
...

Sheet ГраницыИзделий3
A1: Стойка | B1: ЛеваяСтойка | C1: ПраваяСтойка | D1: НомерИзделия
A2: 1 | B2: 1 | C2: 35 | D2: 1
A3: 2 | B3: 1 | C3: 35 | D3: 1
A4: 3 | B4: 1 | C4: 35 | D4: 1
A5: 4 | B5: 1 | C5: 35 | D5: 1
A6: 5 | B6: 1 | C6: 35 | D6: 1
A7: 6 | B7: 1 | C7: 35 | D7: 1
A8: 7 | B8: 1 | C8: 35 | D8: 1
A9: 8 | B9: 1 | C9: 35 | D9: 1
A10: 9 | B10: 1 | C10: 35 | D10: 1
A11: 10 | B11: 1 | C11: 35 | D11: 1
A12: 11 | B12: 1 | C12: 35 | D12: 1
A13: 12 | B13: 1 | C13: 35 | D13: 1
... A36: 35 | B36: 1 | C36: 35 | D36: 1

Sheet Изделия3
A1: Этаж | B1: с1
A2: 57 | B2: ВН-24-К5(б)-1
A3: 56 | B3: ВН-22-К5(б)-1
A4: 55 | B4: ВН-23-К5(б)-1
A5: 54 | B5: ВН-22-К5(б)-1
A6: 53 | B6: ВН-23-К5(б)-1
A7: 52 | B7: ВН-22-К5(б)-1
A8: 51 | B8: ВН-23-К5(б)-1
A9: 50 | B9: ВН-22-К5(б)-1
A10: 49 | B10: ВН-23-К5(б)-1
A11: 48 | B11: ВН-22-К5(б)-1
A12: 47 | B12: ВН-23-К5(б)-1
A13: 46 | B13: ВН-22-К5(б)-1
... A57: 2 | B57: ВН-22-К5(а)-1

Sheet Размещение изделий3
A1: пп | B1: Изделие | C1: Этажи | D1: Кол-во изделий
A2: 1 | B2: ВН-22-К5(а)-1 | C2: Чётные 2,4,…,28 | D2: 14
A3: 2 | B3: ВН-23-К5(а)-1 | C3: Нечётные 3,5,…,17,21,…,27 | D3: 12
A4: 3 | B4: ВН-23-К5(а)-2 | C4: 19 | D4: 1
A5: 4 | B5: ВН-23-К5(б)-1 | C5: Нечётные 29,31,…,37,41,…,55 | D5: 13
A6: 5 | B6: ВН-22-К5(б)-1 | C6: Чётные 30,32,…,56 | D6: 14
A7: 6 | B7: ВН-23-К5(б)-2 | C7: 39 | D7: 1
A8: 7 | B8: ВН-24-К5(б)-1 | C8: 57 | D8: 1

Sheet Подсчёт изделий3
A1: РядИзделий | B1: Этаж | C1: Изделие | D1: Количество
A2: 1 | B2: =Изделия3!A2 -> 57 | C2: =Изделия3!B2 -> ВН-24-К5(б)-1 | D2: 1
A3: 1 | B3: =Изделия3!A3 -> 56 | C3: =Изделия3!B3 -> ВН-22-К5(б)-1 | D3: 1
A4: 1 | B4: =Изделия3!A4 -> 55 | C4: =Изделия3!B4 -> ВН-23-К5(б)-1 | D4: 1
A5: 1 | B5: =Изделия3!A5 -> 54 | C5: =Изделия3!B5 -> ВН-22-К5(б)-1 | D5: 1
A6: 1 | B6: =Изделия3!A6 -> 53 | C6: =Изделия3!B6 -> ВН-23-К5(б)-1 | D6: 1
A7: 1 | B7: =Изделия3!A7 -> 52 | C7: =Изделия3!B7 -> ВН-22-К5(б)-1 | D7: 1
A8: 1 | B8: =Изделия3!A8 -> 51 | C8: =Изделия3!B8 -> ВН-23-К5(б)-1 | D8: 1
A9: 1 | B9: =Изделия3!A9 -> 50 | C9: =Изделия3!B9 -> ВН-22-К5(б)-1 | D9: 1
A10: 1 | B10: =Изделия3!A10 -> 49 | C10: =Изделия3!B10 -> ВН-23-К5(б)-1 | D10: 1
A11: 1 | B11: =Изделия3!A11 -> 48 | C11: =Изделия3!B11 -> ВН-22-К5(б)-1 | D11: 1
A12: 1 | B12: =Изделия3!A12 -> 47 | C12: =Изделия3!B12 -> ВН-23-К5(б)-1 | D12: 1
A13: 1 | B13: =Изделия3!A13 -> 46 | C13: =Изделия3!B13 -> ВН-22-К5(б)-1 | D13: 1
... A57: 1 | B57: =Изделия3!A57 -> 2 | C57: =Изделия3!B57 -> ВН-22-К5(а)-1 | D57: 1

Sheet Сводная таблица_Подсчёт изделий
A1: Изделие | B1: Сумма - Количество
A2: ВН-22-К5(а)-1 | B2: 14
A3: ВН-22-К5(б)-1 | B3: 14
A4: ВН-23-К5(а)-1 | B4: 12
A5: ВН-23-К5(а)-2 | B5: 1
A6: ВН-23-К5(б)-1 | B6: 13
A7: ВН-23-К5(б)-2 | B7: 1
A8: ВН-24-К5(б)-1 | B8: 1
A9: Итог Результат | B9: 56

Sheet Data
B1: Заполнения | D1: ТипРядовЗаполнений | F1: ТипКреплений | H1: Подпорки | J1: Опоры | L1: Термомосты | N1: Крепление ригеля | P1: Подставка | R1: Опоры | T1: Ряды опор
B2: 3а | D2: Зап1 | F2: Креп1 | H2: Подпорка1 | J2: о1 | L2: т0 | N2: с1 | P2: Подставка | R2: о1лев | T2: ОпораМ
B3: 5а | D3: Зап1_20 | F3: Креп1_20 | H3: Подпорка1_20 | J3: о1лев | L3: тСтойка | N3: с2 | R3: о1прав | T3: ОпораМ_Ус
B4: 6а2 | D4: Зап2 | F4: Креп2 | H4: Подпорка2 | J4: о1прав | L4: т13 | N4: с3 | R4: о1 | T4: Опора1
B5: Тип 10 | D5: Зап2_57 | F5: Креп2_57 | H5: Подпорка2_57 | J5: о2 | L5: т24 | N5: с4 | R5: о2лев | T5: Опора1_20
D6: Межэтажка | F6: КрепМ | J6: о2лев | L6: т1 | N6: с2ус | R6: о2прав | T6: Опора1_40
B7: ВС | D7: Базовый | F7: КрепМ_Ус | H7: пл2_Подпорка1 | J7: о2прав | L7: т2 | N7: с6 | R7: о2
B8: ОК-1 | D8: ЗапНизВерх | H8: пл2_Подпорка2 | J8: о3 | L8: т3 | N8: с7 | T8: Опора2
B9: ОК-1.1 | D9: Термомост | H9: пл2_Подпорка2_57 | J9: о3лев | L9: т4 | N9: с80 | T9: Опора2_57
B10: 3б | D10: пл2_Зап1 | F10: пл2_Креп1 | J10: о3прав
B11: 1а | D11: пл2_Зап2 | F11: пл2_Креп2 | J11: о4
B12: 1б | D12: пл2_Зап2_57 | F12: пл2_КрепМ | J12: о5
D13: пл2_Межэтажка | F13: пл2_КрепМУс | J13: о4лев
B14: 5б | D14: пл2_Базовый | J14: o4прав
B15: 6а | D15: пл2_ЗапНизВерх | F15: ВС
B16: 6б
B17: Тип 8 | D17: ВС
B18: 7б | D18: ххх
B19: ВС
B20: СН
B21: Лист 2 мм
B22: Лист 1 мм
B23: Продлить
B24: НВС
